

try{
    let x = 10;

    console.log(x);// referance error
    console.log("working")

}
catch(error){
    console.log("server is under maintance");

} 